Workbook

Sheet Anleitung
A1: Angebotskalkulator - Handwerk & Logistik
A4: Was die Datei tut | B4: Aus Aufmaß und Leistungen berechnet sie Stunden, Material, Selbstkosten und daraus einen belastbaren Angebotspreis - inklusive druckfertigem Angebot.
A6: Farblegende
A7: blaue Schrift | B7: Eingabefeld - hier tragen Sie Ihre Werte ein.
A8: schwarze Schrift | B8: Formel - bitte nicht überschreiben.
A9: grüne Schrift | B9: Verweis auf ein anderes Tabellenblatt.
A10: gelbe Füllung | B10: Schlüsselannahme - vor dem ersten Angebot einmal prüfen und anpassen.
A12: In dieser Reihenfolge
A13: 1. Stammdaten | B13: Firmendaten eintragen und die Kalkulationsgrößen auf den eigenen Betrieb einstellen. Wichtigster Wert: der Mittellohn.
A14: 2. Leistungskatalog | B14: Eigene Leistungen ergänzen: Zeit je Einheit und Materialkosten je Einheit. Die Katalog-Nr. ist der Schlüssel, über den die Kalkulation zugreift.
A15: 3. Kalkulation | B15: Kunde und Aufmaß eintragen, dann je Position eine Katalog-Nr. wählen und die Menge setzen. Mengen dürfen auf den Aufmaß-Block verweisen, z. B. =B16 für die Wandfläche.
A16: 4. Angebot | B16: Wird automatisch gefüllt und ist auf A4 druckfertig eingerichtet - drucken oder als PDF exportieren.
A18: Beispiel enthalten | B18: Vorbelegt ist 'Wohnung 45 m² komplett streichen' inkl. Vorarbeiten und Türen. Einfach die Zahlen im Aufmaß-Block überschreiben - alles rechnet sich neu.
A20: Rechenweg je Position | B20: Stunden = Menge x Zeit/Einheit | Lohnkosten = Stunden x Mittellohn | Material = Menge x Material/Einheit
B21: Selbstkosten = Lohnkosten x (1 + GK Lohn) + Material x (1 + GK Material)
B22: Einheitspreis = Selbstkosten x (1 + Wagnis & Gewinn) x (1 + Skonto) / Menge
A24: Rechenweg Summe | B24: Positionen + An-/Abfahrt - Rabatt = Nettobetrag; zzgl. USt = Gesamtbetrag brutto.
A25: Warum Skonto im Preis | B25: Der Skontosatz steckt im Einheitspreis statt in einer eigenen Summenzeile. So geht das gedruckte Angebot für den Kunden sauber auf, und ein gezogenes Skonto kostet keine Marge.
A27: Hinweis zu den Vorgabewerten | B27: Zeit- und Materialansätze im Katalog sind Branchen-Richtwerte zur Orientierung, keine verbindliche Kalkulation. Maßgeblich sind die Werte des eigenen Betriebs.

Sheet Stammdaten
A1: Stammdaten und Kalkulationsgrößen
A3: Firmendaten (erscheinen im Angebotskopf)
A4: Firmenname | B4: Muster Malerbetrieb GmbH
A5: Straße, Nr. | B5: Handwerkerweg 12
A6: PLZ / Ort | B6: 12345 Musterstadt
A7: Telefon | B7: 0123 456789
A8: E-Mail | B8: info@muster-malerbetrieb.de
A9: USt-IdNr. | B9: DE123456789
A10: IBAN | B10: DE00 0000 0000 0000 0000 00
A13: Kalkulationsgrößen
A14: Mittellohn (Kosten je produktiver Stunde) | B14: 42 | C14: Bruttolohn + Lohnnebenkosten / produktive Stunden. Richtwert - durch eigenen Wert ersetzen.
A15: Gemeinkostenzuschlag auf Lohn | B15: 0.25 | C15: Büro, Fahrzeuge, Werkzeug, Versicherung, unproduktive Zeiten.
A16: Gemeinkostenzuschlag auf Material | B16: 0.1 | C16: Beschaffung, Lagerung, Verschnitt.
A17: Wagnis & Gewinn | B17: 0.12 | C17: Aufschlag auf die Selbstkosten. Handwerk üblich 8-15 %.
A18: Rabatt (auf Angebotssumme) | B18: 0 | C18: Optionaler Nachlass. 0 = kein Rabatt.
A19: Skonto (einkalkuliert) | B19: 0.02 | C19: Wird auf den Preis aufgeschlagen, damit ein gezogenes Skonto die Marge nicht auffrisst.
A20: Fahrtkosten je km | B20: 0.7 | C20: Kilometersatz Nutzfahrzeug inkl. Verschleiß.
A21: Umsatzsteuersatz | B21: 0.19 | C21: 19 % Regelsatz. Bei Kleinunternehmer nach § 19 UStG auf 0 setzen.
A22: Zahlungsziel (Tage) | B22: 14 | C22: Erscheint im Angebotstext.
A23: Angebot gültig (Tage) | B23: 30 | C23: Bindefrist ab Angebotsdatum.
A25: Alle Vorgabewerte sind Branchen-Richtwerte und vom Nutzer zu prüfen. Quelle der Zahlen: Vorbelegung dieser Vorlage, keine externe Preisliste.

Sheet Leistungskatalog
A1: Leistungskatalog
A2: Katalog-Nr. ist der Schlüssel für das Blatt 'Kalkulation'. Eigene Leistungen einfach in freien Zeilen ergänzen.
A3: Nr. | B3: Gewerk | C3: Leistung | D3: Einheit | E3: Zeit/Einheit (Std) | F3: Material/Einheit (€) | G3: Hinweis
A4: M01 | B4: Maler | C4: Böden und Mobiliar abdecken, Kanten abkleben | D4: m² | E4: 0.05 | F4: 0.35 | G4: Bezug: Bodenfläche
A5: M02 | B5: Maler | C5: Untergrund reinigen und vorbereiten | D5: m² | E5: 0.04 | F5: 0.1
A6: M03 | B6: Maler | C6: Risse und Löcher spachteln, schleifen | D6: m² | E6: 0.06 | F6: 0.45 | G6: Nur anteilige Fläche ansetzen
A7: M04 | B7: Maler | C7: Tiefengrund / Haftgrund auftragen | D7: m² | E7: 0.03 | F7: 0.55
A8: M05 | B8: Maler | C8: Wände streichen, 2 Anstriche Dispersion | D8: m² | E8: 0.12 | F8: 1.25 | G8: Farbe ca. 0,35 l/m²
A9: M06 | B9: Maler | C9: Decken streichen, 2 Anstriche Dispersion | D9: m² | E9: 0.15 | F9: 1.25 | G9: Über Kopf, höherer Zeitansatz
A10: M07 | B10: Maler | C10: Fenster- und Heizkörpernischen streichen | D10: m² | E10: 0.25 | F10: 1.6 | G10: Kleinteilig
A11: M08 | B11: Maler | C11: Türblatt lackieren, beidseitig | D11: Stk | E11: 1.2 | F11: 12
A12: M09 | B12: Maler | C12: Türzarge lackieren | D12: Stk | E12: 0.8 | F12: 7.5
A13: M10 | B13: Maler | C13: Endreinigung und Abfallentsorgung | D13: m² | E13: 0.04 | F13: 0.25 | G13: Bezug: Bodenfläche
A14: M11 | B14: Maler | C14: Raufasertapete entfernen | D14: m² | E14: 0.18 | F14: 0.3
A15: M12 | B15: Maler | C15: An- und Abfahrt, Rüst- und Räumzeit | D15: pausch. | E15: 1.5 | F15: 0 | G15: Je Einsatz
A16: T01 | B16: Trockenbau | C16: Gipskartonwand beplanken, einlagig | D16: m² | E16: 0.35 | F16: 14.5
A17: T02 | B17: Trockenbau | C17: Fugen spachteln Q2 | D17: m² | E17: 0.12 | F17: 1.1
A18: B01 | B18: Boden | C18: Laminat verlegen inkl. Trittschall | D18: m² | E18: 0.25 | F18: 18
A19: B02 | B19: Boden | C19: Sockelleisten montieren | D19: m | E19: 0.1 | F19: 4.2
A20: E01 | B20: Elektro | C20: Steckdose / Schalter tauschen | D20: Stk | E20: 0.35 | F20: 6.5
A21: E02 | B21: Elektro | C21: Leuchte montieren und anschließen | D21: Stk | E21: 0.5 | F21: 0 | G21: Leuchte bauseits
A22: L01 | B22: Logistik | C22: Be- und Entladen (Personalstunde) | D22: Std | E22: 1 | F22: 0
A23: L02 | B23: Logistik | C23: Transportfahrt Nutzfahrzeug | D23: km | E23: 0.02 | F23: 0.45 | G23: Zeit + Betriebskosten je km
A24: L03 | B24: Logistik | C24: Umzugskarton packen inkl. Material | D24: Stk | E24: 0.12 | F24: 2.2
A25: L04 | B25: Logistik | C25: Möbeldemontage / -montage | D25: Std | E25: 1 | F25: 0
A26: L05 | B26: Logistik | C26: Einlagerung je m³ und Monat | D26: m³ | E26: 0.05 | F26: 8
A27: L06 | B27: Logistik | C27: Halteverbotszone beantragen und stellen | D27: pausch. | E27: 1 | F27: 95
A29: Zeit- und Materialansätze sind Richtwerte dieser Vorlage zur Orientierung (keine externe Preisliste) und durch die eigenen Nachkalkulationswerte zu ersetzen.

Sheet Kalkulation
A1: Angebotskalkulation
A2: Kunde und Vorgang
A3: Kunde / Auftraggeber | B3: Familie Beispiel
A4: Straße, Nr. | B4: Beispielstrasse 7
A5: PLZ / Ort | B5: 12345 Musterstadt
A6: Bauvorhaben / Objekt | B6: Wohnung 45 m², komplett streichen
A7: Angebotsnummer | B7: 2026-0001
A8: Angebotsdatum | B8: =TODAY() -> 46249
A10: Aufmaß-Helfer (Eingaben blau, Ergebnisse schwarz)
A11: Wohnfläche (m²) | B11: 45 | C11: Grundfläche der zu bearbeitenden Räume.
A12: Raumhöhe (m) | B12: 2.5 | C12: Nur informativ / für eigenes Nachrechnen.
A13: Faktor Wandfläche je m² Wohnfläche | B13: 2.5 | C13: Faustwert für Wohnungen mit mehreren Räumen: 2,3-2,8. Bei einem einzelnen großen Raum niedriger ansetzen.
A14: Wandfläche brutto (m²) | B14: =ROUND($B$11*$B$13,2) -> 112.5
A15: Abzug Fenster und Türen (m²) | B15: 12 | C15: Summe der nicht zu streichenden Flächen.
A16: Wandfläche netto (m²) | B16: =ROUND(MAX(0,$B$14-$B$15),2) -> 100.5
A17: Deckenfläche (m²) | B17: =$B$11 -> 45
A18: Bodenfläche zum Abdecken (m²) | B18: =$B$11 -> 45
A19: Anzahl Türen (Stk) | B19: 4
A20: Anteil Spachtel-/Ausbesserungsfläche | B20: 0.3 | C20: Wie viel Prozent der Fläche muss tatsächlich gespachtelt werden.
A21: Fahrstrecke gesamt (km, hin und zurück) | B21: 40
A23: Positionen
A24: Pos | B24: Kat.-Nr. | C24: Leistung | D24: Einheit | E24: Menge | F24: Zeit/Einh. (Std) | G24: Stunden | H24: Lohnkosten (€) | I24: Material/Einh. (€) | J24: Material (€) | K24: Selbstkosten (€) | L24: EP netto (€) | M24: GP netto (€)
A25: 1 | B25: M12 | C25: =IFERROR(INDEX(Leistungskatalog!$C$4:$C$27,MATCH($B25,Leistungskatalog!$A$4:$A$27,0)),"") -> An- und Abfahrt, Rüst- und Räumzeit | D25: =IFERROR(INDEX(Leistungskatalog!$D$4:$D$27,MATCH($B25,Leistungskatalog!$A$4:$A$27,0)),"") -> pausch. | E25: 1 | F25: =IFERROR(INDEX(Leistungskatalog!$E$4:$E$27,MATCH($B25,Leistungskatalog!$A$4:$A$27,0)),0) -> 1.5 | G25: =IF($B25="","",ROUND($E25*$F25,2)) -> 1.5 | H25: =IF($B25="","",ROUND($G25*Stammdaten!$B$14,2)) -> 63 | I25: =IFERROR(INDEX(Leistungskatalog!$F$4:$F$27,MATCH($B25,Leistungskatalog!$A$4:$A$27,0)),0) -> 0 | J25: =IF($B25="","",ROUND($E25*$I25,2)) -> 0 | K25: =IF($B25="","",ROUND($H25*(1+Stammdaten!$B$15)+$J25*(1+Stammdaten!$B$16),2)) -> 78.75 | L25: =IF($B25="","",IFERROR(ROUND($K25*(1+Stammdaten!$B$17)*(1+Stammdaten!$B$19)/$E25,2),0)) -> 89.96 | M25: =IF($B25="","",ROUND($L25*$E25,2)) -> 89.96
A26: 2 | B26: M01 | C26: =IFERROR(INDEX(Leistungskatalog!$C$4:$C$27,MATCH($B26,Leistungskatalog!$A$4:$A$27,0)),"") -> Böden und Mobiliar abdecken, Kanten abkleben | D26: =IFERROR(INDEX(Leistungskatalog!$D$4:$D$27,MATCH($B26,Leistungskatalog!$A$4:$A$27,0)),"") -> m² | E26: =$B$18 -> 45 | F26: =IFERROR(INDEX(Leistungskatalog!$E$4:$E$27,MATCH($B26,Leistungskatalog!$A$4:$A$27,0)),0) -> 0.05 | G26: =IF($B26="","",ROUND($E26*$F26,2)) -> 2.25 | H26: =IF($B26="","",ROUND($G26*Stammdaten!$B$14,2)) -> 94.5 | I26: =IFERROR(INDEX(Leistungskatalog!$F$4:$F$27,MATCH($B26,Leistungskatalog!$A$4:$A$27,0)),0) -> 0.35 | J26: =IF($B26="","",ROUND($E26*$I26,2)) -> 15.75 | K26: =IF($B26="","",ROUND($H26*(1+Stammdaten!$B$15)+$J26*(1+Stammdaten!$B$16),2)) -> 135.45 | L26: =IF($B26="","",IFERROR(ROUND($K26*(1+Stammdaten!$B$17)*(1+Stammdaten!$B$19)/$E26,2),0)) -> 3.44 | M26: =IF($B26="","",ROUND($L26*$E26,2)) -> 154.8
A27: 3 | B27: M02 | C27: =IFERROR(INDEX(Leistungskatalog!$C$4:$C$27,MATCH($B27,Leistungskatalog!$A$4:$A$27,0)),"") -> Untergrund reinigen und vorbereiten | D27: =IFERROR(INDEX(Leistungskatalog!$D$4:$D$27,MATCH($B27,Leistungskatalog!$A$4:$A$27,0)),"") -> m² | E27: =$B$16+$B$17 -> 145.5 | F27: =IFERROR(INDEX(Leistungskatalog!$E$4:$E$27,MATCH($B27,Leistungskatalog!$A$4:$A$27,0)),0) -> 0.04 | G27: =IF($B27="","",ROUND($E27*$F27,2)) -> 5.82 | H27: =IF($B27="","",ROUND($G27*Stammdaten!$B$14,2)) -> 244.44 | I27: =IFERROR(INDEX(Leistungskatalog!$F$4:$F$27,MATCH($B27,Leistungskatalog!$A$4:$A$27,0)),0) -> 0.1 | J27: =IF($B27="","",ROUND($E27*$I27,2)) -> 14.55 | K27: =IF($B27="","",ROUND($H27*(1+Stammdaten!$B$15)+$J27*(1+Stammdaten!$B$16),2)) -> 321.56 | L27: =IF($B27="","",IFERROR(ROUND($K27*(1+Stammdaten!$B$17)*(1+Stammdaten!$B$19)/$E27,2),0)) -> 2.52 | M27: =IF($B27="","",ROUND($L27*$E27,2)) -> 366.66
A28: 4 | B28: M03 | C28: =IFERROR(INDEX(Leistungskatalog!$C$4:$C$27,MATCH($B28,Leistungskatalog!$A$4:$A$27,0)),"") -> Risse und Löcher spachteln, schleifen | D28: =IFERROR(INDEX(Leistungskatalog!$D$4:$D$27,MATCH($B28,Leistungskatalog!$A$4:$A$27,0)),"") -> m² | E28: =ROUND(($B$16+$B$17)*$B$20,1) -> 43.7 | F28: =IFERROR(INDEX(Leistungskatalog!$E$4:$E$27,MATCH($B28,Leistungskatalog!$A$4:$A$27,0)),0) -> 0.06 | G28: =IF($B28="","",ROUND($E28*$F28,2)) -> 2.62 | H28: =IF($B28="","",ROUND($G28*Stammdaten!$B$14,2)) -> 110.04 | I28: =IFERROR(INDEX(Leistungskatalog!$F$4:$F$27,MATCH($B28,Leistungskatalog!$A$4:$A$27,0)),0) -> 0.45 | J28: =IF($B28="","",ROUND($E28*$I28,2)) -> 19.67 | K28: =IF($B28="","",ROUND($H28*(1+Stammdaten!$B$15)+$J28*(1+Stammdaten!$B$16),2)) -> 159.19 | L28: =IF($B28="","",IFERROR(ROUND($K28*(1+Stammdaten!$B$17)*(1+Stammdaten!$B$19)/$E28,2),0)) -> 4.16 | M28: =IF($B28="","",ROUND($L28*$E28,2)) -> 181.79
A29: 5 | B29: M04 | C29: =IFERROR(INDEX(Leistungskatalog!$C$4:$C$27,MATCH($B29,Leistungskatalog!$A$4:$A$27,0)),"") -> Tiefengrund / Haftgrund auftragen | D29: =IFERROR(INDEX(Leistungskatalog!$D$4:$D$27,MATCH($B29,Leistungskatalog!$A$4:$A$27,0)),"") -> m² | E29: =$B$16+$B$17 -> 145.5 | F29: =IFERROR(INDEX(Leistungskatalog!$E$4:$E$27,MATCH($B29,Leistungskatalog!$A$4:$A$27,0)),0) -> 0.03 | G29: =IF($B29="","",ROUND($E29*$F29,2)) -> 4.37 | H29: =IF($B29="","",ROUND($G29*Stammdaten!$B$14,2)) -> 183.54 | I29: =IFERROR(INDEX(Leistungskatalog!$F$4:$F$27,MATCH($B29,Leistungskatalog!$A$4:$A$27,0)),0) -> 0.55 | J29: =IF($B29="","",ROUND($E29*$I29,2)) -> 80.03 | K29: =IF($B29="","",ROUND($H29*(1+Stammdaten!$B$15)+$J29*(1+Stammdaten!$B$16),2)) -> 317.46 | L29: =IF($B29="","",IFERROR(ROUND($K29*(1+Stammdaten!$B$17)*(1+Stammdaten!$B$19)/$E29,2),0)) -> 2.49 | M29: =IF($B29="","",ROUND($L29*$E29,2)) -> 362.3
A30: 6 | B30: M05 | C30: =IFERROR(INDEX(Leistungskatalog!$C$4:$C$27,MATCH($B30,Leistungskatalog!$A$4:$A$27,0)),"") -> Wände streichen, 2 Anstriche Dispersion | D30: =IFERROR(INDEX(Leistungskatalog!$D$4:$D$27,MATCH($B30,Leistungskatalog!$A$4:$A$27,0)),"") -> m² | E30: =$B$16 -> 100.5 | F30: =IFERROR(INDEX(Leistungskatalog!$E$4:$E$27,MATCH($B30,Leistungskatalog!$A$4:$A$27,0)),0) -> 0.12 | G30: =IF($B30="","",ROUND($E30*$F30,2)) -> 12.06 | H30: =IF($B30="","",ROUND($G30*Stammdaten!$B$14,2)) -> 506.52 | I30: =IFERROR(INDEX(Leistungskatalog!$F$4:$F$27,MATCH($B30,Leistungskatalog!$A$4:$A$27,0)),0) -> 1.25 | J30: =IF($B30="","",ROUND($E30*$I30,2)) -> 125.63 | K30: =IF($B30="","",ROUND($H30*(1+Stammdaten!$B$15)+$J30*(1+Stammdaten!$B$16),2)) -> 771.34 | L30: =IF($B30="","",IFERROR(ROUND($K30*(1+Stammdaten!$B$17)*(1+Stammdaten!$B$19)/$E30,2),0)) -> 8.77 | M30: =IF($B30="","",ROUND($L30*$E30,2)) -> 881.39
A31: 7 | B31: M06 | C31: =IFERROR(INDEX(Leistungskatalog!$C$4:$C$27,MATCH($B31,Leistungskatalog!$A$4:$A$27,0)),"") -> Decken streichen, 2 Anstriche Dispersion | D31: =IFERROR(INDEX(Leistungskatalog!$D$4:$D$27,MATCH($B31,Leistungskatalog!$A$4:$A$27,0)),"") -> m² | E31: =$B$17 -> 45 | F31: =IFERROR(INDEX(Leistungskatalog!$E$4:$E$27,MATCH($B31,Leistungskatalog!$A$4:$A$27,0)),0) -> 0.15 | G31: =IF($B31="","",ROUND($E31*$F31,2)) -> 6.75 | H31: =IF($B31="","",ROUND($G31*Stammdaten!$B$14,2)) -> 283.5 | I31: =IFERROR(INDEX(Leistungskatalog!$F$4:$F$27,MATCH($B31,Leistungskatalog!$A$4:$A$27,0)),0) -> 1.25 | J31: =IF($B31="","",ROUND($E31*$I31,2)) -> 56.25 | K31: =IF($B31="","",ROUND($H31*(1+Stammdaten!$B$15)+$J31*(1+Stammdaten!$B$16),2)) -> 416.25 | L31: =IF($B31="","",IFERROR(ROUND($K31*(1+Stammdaten!$B$17)*(1+Stammdaten!$B$19)/$E31,2),0)) -> 10.57 | M31: =IF($B31="","",ROUND($L31*$E31,2)) -> 475.65
A32: 8 | B32: M09 | C32: =IFERROR(INDEX(Leistungskatalog!$C$4:$C$27,MATCH($B32,Leistungskatalog!$A$4:$A$27,0)),"") -> Türzarge lackieren | D32: =IFERROR(INDEX(Leistungskatalog!$D$4:$D$27,MATCH($B32,Leistungskatalog!$A$4:$A$27,0)),"") -> Stk | E32: =$B$19 -> 4 | F32: =IFERROR(INDEX(Leistungskatalog!$E$4:$E$27,MATCH($B32,Leistungskatalog!$A$4:$A$27,0)),0) -> 0.8 | G32: =IF($B32="","",ROUND($E32*$F32,2)) -> 3.2 | H32: =IF($B32="","",ROUND($G32*Stammdaten!$B$14,2)) -> 134.4 | I32: =IFERROR(INDEX(Leistungskatalog!$F$4:$F$27,MATCH($B32,Leistungskatalog!$A$4:$A$27,0)),0) -> 7.5 | J32: =IF($B32="","",ROUND($E32*$I32,2)) -> 30 | K32: =IF($B32="","",ROUND($H32*(1+Stammdaten!$B$15)+$J32*(1+Stammdaten!$B$16),2)) -> 201 | L32: =IF($B32="","",IFERROR(ROUND($K32*(1+Stammdaten!$B$17)*(1+Stammdaten!$B$19)/$E32,2),0)) -> 57.41 | M32: =IF($B32="","",ROUND($L32*$E32,2)) -> 229.64
A33: 9 | B33: M08 | C33: =IFERROR(INDEX(Leistungskatalog!$C$4:$C$27,MATCH($B33,Leistungskatalog!$A$4:$A$27,0)),"") -> Türblatt lackieren, beidseitig | D33: =IFERROR(INDEX(Leistungskatalog!$D$4:$D$27,MATCH($B33,Leistungskatalog!$A$4:$A$27,0)),"") -> Stk | E33: =$B$19 -> 4 | F33: =IFERROR(INDEX(Leistungskatalog!$E$4:$E$27,MATCH($B33,Leistungskatalog!$A$4:$A$27,0)),0) -> 1.2 | G33: =IF($B33="","",ROUND($E33*$F33,2)) -> 4.8 | H33: =IF($B33="","",ROUND($G33*Stammdaten!$B$14,2)) -> 201.6 | I33: =IFERROR(INDEX(Leistungskatalog!$F$4:$F$27,MATCH($B33,Leistungskatalog!$A$4:$A$27,0)),0) -> 12 | J33: =IF($B33="","",ROUND($E33*$I33,2)) -> 48 | K33: =IF($B33="","",ROUND($H33*(1+Stammdaten!$B$15)+$J33*(1+Stammdaten!$B$16),2)) -> 304.8 | L33: =IF($B33="","",IFERROR(ROUND($K33*(1+Stammdaten!$B$17)*(1+Stammdaten!$B$19)/$E33,2),0)) -> 87.05 | M33: =IF($B33="","",ROUND($L33*$E33,2)) -> 348.2
A34: 10 | B34: M10 | C34: =IFERROR(INDEX(Leistungskatalog!$C$4:$C$27,MATCH($B34,Leistungskatalog!$A$4:$A$27,0)),"") -> Endreinigung und Abfallentsorgung | D34: =IFERROR(INDEX(Leistungskatalog!$D$4:$D$27,MATCH($B34,Leistungskatalog!$A$4:$A$27,0)),"") -> m² | E34: =$B$18 -> 45 | F34: =IFERROR(INDEX(Leistungskatalog!$E$4:$E$27,MATCH($B34,Leistungskatalog!$A$4:$A$27,0)),0) -> 0.04 | G34: =IF($B34="","",ROUND($E34*$F34,2)) -> 1.8 | H34: =IF($B34="","",ROUND($G34*Stammdaten!$B$14,2)) -> 75.6 | I34: =IFERROR(INDEX(Leistungskatalog!$F$4:$F$27,MATCH($B34,Leistungskatalog!$A$4:$A$27,0)),0) -> 0.25 | J34: =IF($B34="","",ROUND($E34*$I34,2)) -> 11.25 | K34: =IF($B34="","",ROUND($H34*(1+Stammdaten!$B$15)+$J34*(1+Stammdaten!$B$16),2)) -> 106.88 | L34: =IF($B34="","",IFERROR(ROUND($K34*(1+Stammdaten!$B$17)*(1+Stammdaten!$B$19)/$E34,2),0)) -> 2.71 | M34: =IF($B34="","",ROUND($L34*$E34,2)) -> 121.95
A35: 11 | C35: =IFERROR(INDEX(Leistungskatalog!$C$4:$C$27,MATCH($B35,Leistungskatalog!$A$4:$A$27,0)),"") | D35: =IFERROR(INDEX(Leistungskatalog!$D$4:$D$27,MATCH($B35,Leistungskatalog!$A$4:$A$27,0)),"") | F35: =IFERROR(INDEX(Leistungskatalog!$E$4:$E$27,MATCH($B35,Leistungskatalog!$A$4:$A$27,0)),0) -> 0 | G35: =IF($B35="","",ROUND($E35*$F35,2)) | H35: =IF($B35="","",ROUND($G35*Stammdaten!$B$14,2)) | I35: =IFERROR(INDEX(Leistungskatalog!$F$4:$F$27,MATCH($B35,Leistungskatalog!$A$4:$A$27,0)),0) -> 0 | J35: =IF($B35="","",ROUND($E35*$I35,2)) | K35: =IF($B35="","",ROUND($H35*(1+Stammdaten!$B$15)+$J35*(1+Stammdaten!$B$16),2)) | L35: =IF($B35="","",IFERROR(ROUND($K35*(1+Stammdaten!$B$17)*(1+Stammdaten!$B$19)/$E35,2),0)) | M35: =IF($B35="","",ROUND($L35*$E35,2))
A36: 12 | C36: =IFERROR(INDEX(Leistungskatalog!$C$4:$C$27,MATCH($B36,Leistungskatalog!$A$4:$A$27,0)),"") | D36: =IFERROR(INDEX(Leistungskatalog!$D$4:$D$27,MATCH($B36,Leistungskatalog!$A$4:$A$27,0)),"") | F36: =IFERROR(INDEX(Leistungskatalog!$E$4:$E$27,MATCH($B36,Leistungskatalog!$A$4:$A$27,0)),0) -> 0 | G36: =IF($B36="","",ROUND($E36*$F36,2)) | H36: =IF($B36="","",ROUND($G36*Stammdaten!$B$14,2)) | I36: =IFERROR(INDEX(Leistungskatalog!$F$4:$F$27,MATCH($B36,Leistungskatalog!$A$4:$A$27,0)),0) -> 0 | J36: =IF($B36="","",ROUND($E36*$I36,2)) | K36: =IF($B36="","",ROUND($H36*(1+Stammdaten!$B$15)+$J36*(1+Stammdaten!$B$16),2)) | L36: =IF($B36="","",IFERROR(ROUND($K36*(1+Stammdaten!$B$17)*(1+Stammdaten!$B$19)/$E36,2),0)) | M36: =IF($B36="","",ROUND($L36*$E36,2))
A37: 13 | C37: =IFERROR(INDEX(Leistungskatalog!$C$4:$C$27,MATCH($B37,Leistungskatalog!$A$4:$A$27,0)),"") | D37: =IFERROR(INDEX(Leistungskatalog!$D$4:$D$27,MATCH($B37,Leistungskatalog!$A$4:$A$27,0)),"") | F37: =IFERROR(INDEX(Leistungskatalog!$E$4:$E$27,MATCH($B37,Leistungskatalog!$A$4:$A$27,0)),0) -> 0 | G37: =IF($B37="","",ROUND($E37*$F37,2)) | H37: =IF($B37="","",ROUND($G37*Stammdaten!$B$14,2)) | I37: =IFERROR(INDEX(Leistungskatalog!$F$4:$F$27,MATCH($B37,Leistungskatalog!$A$4:$A$27,0)),0) -> 0 | J37: =IF($B37="","",ROUND($E37*$I37,2)) | K37: =IF($B37="","",ROUND($H37*(1+Stammdaten!$B$15)+$J37*(1+Stammdaten!$B$16),2)) | L37: =IF($B37="","",IFERROR(ROUND($K37*(1+Stammdaten!$B$17)*(1+Stammdaten!$B$19)/$E37,2),0)) | M37: =IF($B37="","",ROUND($L37*$E37,2))
A38: 14 | C38: =IFERROR(INDEX(Leistungskatalog!$C$4:$C$27,MATCH($B38,Leistungskatalog!$A$4:$A$27,0)),"") | D38: =IFERROR(INDEX(Leistungskatalog!$D$4:$D$27,MATCH($B38,Leistungskatalog!$A$4:$A$27,0)),"") | F38: =IFERROR(INDEX(Leistungskatalog!$E$4:$E$27,MATCH($B38,Leistungskatalog!$A$4:$A$27,0)),0) -> 0 | G38: =IF($B38="","",ROUND($E38*$F38,2)) | H38: =IF($B38="","",ROUND($G38*Stammdaten!$B$14,2)) | I38: =IFERROR(INDEX(Leistungskatalog!$F$4:$F$27,MATCH($B38,Leistungskatalog!$A$4:$A$27,0)),0) -> 0 | J38: =IF($B38="","",ROUND($E38*$I38,2)) | K38: =IF($B38="","",ROUND($H38*(1+Stammdaten!$B$15)+$J38*(1+Stammdaten!$B$16),2)) | L38: =IF($B38="","",IFERROR(ROUND($K38*(1+Stammdaten!$B$17)*(1+Stammdaten!$B$19)/$E38,2),0)) | M38: =IF($B38="","",ROUND($L38*$E38,2))
A39: 15 | C39: =IFERROR(INDEX(Leistungskatalog!$C$4:$C$27,MATCH($B39,Leistungskatalog!$A$4:$A$27,0)),"") | D39: =IFERROR(INDEX(Leistungskatalog!$D$4:$D$27,MATCH($B39,Leistungskatalog!$A$4:$A$27,0)),"") | F39: =IFERROR(INDEX(Leistungskatalog!$E$4:$E$27,MATCH($B39,Leistungskatalog!$A$4:$A$27,0)),0) -> 0 | G39: =IF($B39="","",ROUND($E39*$F39,2)) | H39: =IF($B39="","",ROUND($G39*Stammdaten!$B$14,2)) | I39: =IFERROR(INDEX(Leistungskatalog!$F$4:$F$27,MATCH($B39,Leistungskatalog!$A$4:$A$27,0)),0) -> 0 | J39: =IF($B39="","",ROUND($E39*$I39,2)) | K39: =IF($B39="","",ROUND($H39*(1+Stammdaten!$B$15)+$J39*(1+Stammdaten!$B$16),2)) | L39: =IF($B39="","",IFERROR(ROUND($K39*(1+Stammdaten!$B$17)*(1+Stammdaten!$B$19)/$E39,2),0)) | M39: =IF($B39="","",ROUND($L39*$E39,2))
A40: 16 | C40: =IFERROR(INDEX(Leistungskatalog!$C$4:$C$27,MATCH($B40,Leistungskatalog!$A$4:$A$27,0)),"") | D40: =IFERROR(INDEX(Leistungskatalog!$D$4:$D$27,MATCH($B40,Leistungskatalog!$A$4:$A$27,0)),"") | F40: =IFERROR(INDEX(Leistungskatalog!$E$4:$E$27,MATCH($B40,Leistungskatalog!$A$4:$A$27,0)),0) -> 0 | G40: =IF($B40="","",ROUND($E40*$F40,2)) | H40: =IF($B40="","",ROUND($G40*Stammdaten!$B$14,2)) | I40: =IFERROR(INDEX(Leistungskatalog!$F$4:$F$27,MATCH($B40,Leistungskatalog!$A$4:$A$27,0)),0) -> 0 | J40: =IF($B40="","",ROUND($E40*$I40,2)) | K40: =IF($B40="","",ROUND($H40*(1+Stammdaten!$B$15)+$J40*(1+Stammdaten!$B$16),2)) | L40: =IF($B40="","",IFERROR(ROUND($K40*(1+Stammdaten!$B$17)*(1+Stammdaten!$B$19)/$E40,2),0)) | M40: =IF($B40="","",ROUND($L40*$E40,2))
A41: 17 | C41: =IFERROR(INDEX(Leistungskatalog!$C$4:$C$27,MATCH($B41,Leistungskatalog!$A$4:$A$27,0)),"") | D41: =IFERROR(INDEX(Leistungskatalog!$D$4:$D$27,MATCH($B41,Leistungskatalog!$A$4:$A$27,0)),"") | F41: =IFERROR(INDEX(Leistungskatalog!$E$4:$E$27,MATCH($B41,Leistungskatalog!$A$4:$A$27,0)),0) -> 0 | G41: =IF($B41="","",ROUND($E41*$F41,2)) | H41: =IF($B41="","",ROUND($G41*Stammdaten!$B$14,2)) | I41: =IFERROR(INDEX(Leistungskatalog!$F$4:$F$27,MATCH($B41,Leistungskatalog!$A$4:$A$27,0)),0) -> 0 | J41: =IF($B41="","",ROUND($E41*$I41,2)) | K41: =IF($B41="","",ROUND($H41*(1+Stammdaten!$B$15)+$J41*(1+Stammdaten!$B$16),2)) | L41: =IF($B41="","",IFERROR(ROUND($K41*(1+Stammdaten!$B$17)*(1+Stammdaten!$B$19)/$E41,2),0)) | M41: =IF($B41="","",ROUND($L41*$E41,2))
A42: 18 | C42: =IFERROR(INDEX(Leistungskatalog!$C$4:$C$27,MATCH($B42,Leistungskatalog!$A$4:$A$27,0)),"") | D42: =IFERROR(INDEX(Leistungskatalog!$D$4:$D$27,MATCH($B42,Leistungskatalog!$A$4:$A$27,0)),"") | F42: =IFERROR(INDEX(Leistungskatalog!$E$4:$E$27,MATCH($B42,Leistungskatalog!$A$4:$A$27,0)),0) -> 0 | G42: =IF($B42="","",ROUND($E42*$F42,2)) | H42: =IF($B42="","",ROUND($G42*Stammdaten!$B$14,2)) | I42: =IFERROR(INDEX(Leistungskatalog!$F$4:$F$27,MATCH($B42,Leistungskatalog!$A$4:$A$27,0)),0) -> 0 | J42: =IF($B42="","",ROUND($E42*$I42,2)) | K42: =IF($B42="","",ROUND($H42*(1+Stammdaten!$B$15)+$J42*(1+Stammdaten!$B$16),2)) | L42: =IF($B42="","",IFERROR(ROUND($K42*(1+Stammdaten!$B$17)*(1+Stammdaten!$B$19)/$E42,2),0)) | M42: =IF($B42="","",ROUND($L42*$E42,2))
...

Sheet Angebot
A1: =Stammdaten!$B$4 -> Muster Malerbetrieb GmbH | E1: ANGEBOT
A2: =Stammdaten!$B$5 -> Handwerkerweg 12
A3: =Stammdaten!$B$6 -> 12345 Musterstadt | E3: Angebotsnr. | F3: =Kalkulation!$B$7 -> 2026-0001
A4: ="Tel. "&Stammdaten!$B$7 -> Tel. 0123 456789 | E4: Datum | F4: =Kalkulation!$B$8 -> 46249
A5: =Stammdaten!$B$8 -> info@muster-malerbetrieb.de | E5: Gültig bis | F5: =Kalkulation!$B$8+Stammdaten!$B$23 -> 46279
A8: =Kalkulation!$B$3 -> Familie Beispiel
A9: =Kalkulation!$B$4 -> Beispielstrasse 7
A10: =Kalkulation!$B$5 -> 12345 Musterstadt
A13: ="Bauvorhaben: "&Kalkulation!$B$6 -> Bauvorhaben: Wohnung 45 m², komplett streichen
A14: Sehr geehrte Damen und Herren, vielen Dank für Ihre Anfrage. Für die genannten Leistungen bieten wir Ihnen an:
A16: Pos | B16: Leistung | C16: Menge | D16: Einheit | E16: EP (€) | F16: Gesamt (€)
A17: =IF(Kalkulation!$B$25="","",Kalkulation!$A$25) -> 1 | B17: =IF(Kalkulation!$B$25="","",Kalkulation!$C$25) -> An- und Abfahrt, Rüst- und Räumzeit | C17: =IF(Kalkulation!$B$25="","",Kalkulation!$E$25) -> 1 | D17: =IF(Kalkulation!$B$25="","",Kalkulation!$D$25) -> pausch. | E17: =IF(Kalkulation!$B$25="","",Kalkulation!$L$25) -> 89.96 | F17: =IF(Kalkulation!$B$25="","",Kalkulation!$M$25) -> 89.96
A18: =IF(Kalkulation!$B$26="","",Kalkulation!$A$26) -> 2 | B18: =IF(Kalkulation!$B$26="","",Kalkulation!$C$26) -> Böden und Mobiliar abdecken, Kanten abkleben | C18: =IF(Kalkulation!$B$26="","",Kalkulation!$E$26) -> 45 | D18: =IF(Kalkulation!$B$26="","",Kalkulation!$D$26) -> m² | E18: =IF(Kalkulation!$B$26="","",Kalkulation!$L$26) -> 3.44 | F18: =IF(Kalkulation!$B$26="","",Kalkulation!$M$26) -> 154.8
A19: =IF(Kalkulation!$B$27="","",Kalkulation!$A$27) -> 3 | B19: =IF(Kalkulation!$B$27="","",Kalkulation!$C$27) -> Untergrund reinigen und vorbereiten | C19: =IF(Kalkulation!$B$27="","",Kalkulation!$E$27) -> 145.5 | D19: =IF(Kalkulation!$B$27="","",Kalkulation!$D$27) -> m² | E19: =IF(Kalkulation!$B$27="","",Kalkulation!$L$27) -> 2.52 | F19: =IF(Kalkulation!$B$27="","",Kalkulation!$M$27) -> 366.66
A20: =IF(Kalkulation!$B$28="","",Kalkulation!$A$28) -> 4 | B20: =IF(Kalkulation!$B$28="","",Kalkulation!$C$28) -> Risse und Löcher spachteln, schleifen | C20: =IF(Kalkulation!$B$28="","",Kalkulation!$E$28) -> 43.7 | D20: =IF(Kalkulation!$B$28="","",Kalkulation!$D$28) -> m² | E20: =IF(Kalkulation!$B$28="","",Kalkulation!$L$28) -> 4.16 | F20: =IF(Kalkulation!$B$28="","",Kalkulation!$M$28) -> 181.79
A21: =IF(Kalkulation!$B$29="","",Kalkulation!$A$29) -> 5 | B21: =IF(Kalkulation!$B$29="","",Kalkulation!$C$29) -> Tiefengrund / Haftgrund auftragen | C21: =IF(Kalkulation!$B$29="","",Kalkulation!$E$29) -> 145.5 | D21: =IF(Kalkulation!$B$29="","",Kalkulation!$D$29) -> m² | E21: =IF(Kalkulation!$B$29="","",Kalkulation!$L$29) -> 2.49 | F21: =IF(Kalkulation!$B$29="","",Kalkulation!$M$29) -> 362.3
A22: =IF(Kalkulation!$B$30="","",Kalkulation!$A$30) -> 6 | B22: =IF(Kalkulation!$B$30="","",Kalkulation!$C$30) -> Wände streichen, 2 Anstriche Dispersion | C22: =IF(Kalkulation!$B$30="","",Kalkulation!$E$30) -> 100.5 | D22: =IF(Kalkulation!$B$30="","",Kalkulation!$D$30) -> m² | E22: =IF(Kalkulation!$B$30="","",Kalkulation!$L$30) -> 8.77 | F22: =IF(Kalkulation!$B$30="","",Kalkulation!$M$30) -> 881.39
A23: =IF(Kalkulation!$B$31="","",Kalkulation!$A$31) -> 7 | B23: =IF(Kalkulation!$B$31="","",Kalkulation!$C$31) -> Decken streichen, 2 Anstriche Dispersion | C23: =IF(Kalkulation!$B$31="","",Kalkulation!$E$31) -> 45 | D23: =IF(Kalkulation!$B$31="","",Kalkulation!$D$31) -> m² | E23: =IF(Kalkulation!$B$31="","",Kalkulation!$L$31) -> 10.57 | F23: =IF(Kalkulation!$B$31="","",Kalkulation!$M$31) -> 475.65
A24: =IF(Kalkulation!$B$32="","",Kalkulation!$A$32) -> 8 | B24: =IF(Kalkulation!$B$32="","",Kalkulation!$C$32) -> Türzarge lackieren | C24: =IF(Kalkulation!$B$32="","",Kalkulation!$E$32) -> 4 | D24: =IF(Kalkulation!$B$32="","",Kalkulation!$D$32) -> Stk | E24: =IF(Kalkulation!$B$32="","",Kalkulation!$L$32) -> 57.41 | F24: =IF(Kalkulation!$B$32="","",Kalkulation!$M$32) -> 229.64
A25: =IF(Kalkulation!$B$33="","",Kalkulation!$A$33) -> 9 | B25: =IF(Kalkulation!$B$33="","",Kalkulation!$C$33) -> Türblatt lackieren, beidseitig | C25: =IF(Kalkulation!$B$33="","",Kalkulation!$E$33) -> 4 | D25: =IF(Kalkulation!$B$33="","",Kalkulation!$D$33) -> Stk | E25: =IF(Kalkulation!$B$33="","",Kalkulation!$L$33) -> 87.05 | F25: =IF(Kalkulation!$B$33="","",Kalkulation!$M$33) -> 348.2
A26: =IF(Kalkulation!$B$34="","",Kalkulation!$A$34) -> 10 | B26: =IF(Kalkulation!$B$34="","",Kalkulation!$C$34) -> Endreinigung und Abfallentsorgung | C26: =IF(Kalkulation!$B$34="","",Kalkulation!$E$34) -> 45 | D26: =IF(Kalkulation!$B$34="","",Kalkulation!$D$34) -> m² | E26: =IF(Kalkulation!$B$34="","",Kalkulation!$L$34) -> 2.71 | F26: =IF(Kalkulation!$B$34="","",Kalkulation!$M$34) -> 121.95
A27: =IF(Kalkulation!$B$35="","",Kalkulation!$A$35) | B27: =IF(Kalkulation!$B$35="","",Kalkulation!$C$35) | C27: =IF(Kalkulation!$B$35="","",Kalkulation!$E$35) | D27: =IF(Kalkulation!$B$35="","",Kalkulation!$D$35) | E27: =IF(Kalkulation!$B$35="","",Kalkulation!$L$35) | F27: =IF(Kalkulation!$B$35="","",Kalkulation!$M$35)
A28: =IF(Kalkulation!$B$36="","",Kalkulation!$A$36) | B28: =IF(Kalkulation!$B$36="","",Kalkulation!$C$36) | C28: =IF(Kalkulation!$B$36="","",Kalkulation!$E$36) | D28: =IF(Kalkulation!$B$36="","",Kalkulation!$D$36) | E28: =IF(Kalkulation!$B$36="","",Kalkulation!$L$36) | F28: =IF(Kalkulation!$B$36="","",Kalkulation!$M$36)
A29: =IF(Kalkulation!$B$37="","",Kalkulation!$A$37) | B29: =IF(Kalkulation!$B$37="","",Kalkulation!$C$37) | C29: =IF(Kalkulation!$B$37="","",Kalkulation!$E$37) | D29: =IF(Kalkulation!$B$37="","",Kalkulation!$D$37) | E29: =IF(Kalkulation!$B$37="","",Kalkulation!$L$37) | F29: =IF(Kalkulation!$B$37="","",Kalkulation!$M$37)
A30: =IF(Kalkulation!$B$38="","",Kalkulation!$A$38) | B30: =IF(Kalkulation!$B$38="","",Kalkulation!$C$38) | C30: =IF(Kalkulation!$B$38="","",Kalkulation!$E$38) | D30: =IF(Kalkulation!$B$38="","",Kalkulation!$D$38) | E30: =IF(Kalkulation!$B$38="","",Kalkulation!$L$38) | F30: =IF(Kalkulation!$B$38="","",Kalkulation!$M$38)
A31: =IF(Kalkulation!$B$39="","",Kalkulation!$A$39) | B31: =IF(Kalkulation!$B$39="","",Kalkulation!$C$39) | C31: =IF(Kalkulation!$B$39="","",Kalkulation!$E$39) | D31: =IF(Kalkulation!$B$39="","",Kalkulation!$D$39) | E31: =IF(Kalkulation!$B$39="","",Kalkulation!$L$39) | F31: =IF(Kalkulation!$B$39="","",Kalkulation!$M$39)
A32: =IF(Kalkulation!$B$40="","",Kalkulation!$A$40) | B32: =IF(Kalkulation!$B$40="","",Kalkulation!$C$40) | C32: =IF(Kalkulation!$B$40="","",Kalkulation!$E$40) | D32: =IF(Kalkulation!$B$40="","",Kalkulation!$D$40) | E32: =IF(Kalkulation!$B$40="","",Kalkulation!$L$40) | F32: =IF(Kalkulation!$B$40="","",Kalkulation!$M$40)
A33: =IF(Kalkulation!$B$41="","",Kalkulation!$A$41) | B33: =IF(Kalkulation!$B$41="","",Kalkulation!$C$41) | C33: =IF(Kalkulation!$B$41="","",Kalkulation!$E$41) | D33: =IF(Kalkulation!$B$41="","",Kalkulation!$D$41) | E33: =IF(Kalkulation!$B$41="","",Kalkulation!$L$41) | F33: =IF(Kalkulation!$B$41="","",Kalkulation!$M$41)
A34: =IF(Kalkulation!$B$42="","",Kalkulation!$A$42) | B34: =IF(Kalkulation!$B$42="","",Kalkulation!$C$42) | C34: =IF(Kalkulation!$B$42="","",Kalkulation!$E$42) | D34: =IF(Kalkulation!$B$42="","",Kalkulation!$D$42) | E34: =IF(Kalkulation!$B$42="","",Kalkulation!$L$42) | F34: =IF(Kalkulation!$B$42="","",Kalkulation!$M$42)
A35: =IF(Kalkulation!$B$43="","",Kalkulation!$A$43) | B35: =IF(Kalkulation!$B$43="","",Kalkulation!$C$43) | C35: =IF(Kalkulation!$B$43="","",Kalkulation!$E$43) | D35: =IF(Kalkulation!$B$43="","",Kalkulation!$D$43) | E35: =IF(Kalkulation!$B$43="","",Kalkulation!$L$43) | F35: =IF(Kalkulation!$B$43="","",Kalkulation!$M$43)
A36: =IF(Kalkulation!$B$44="","",Kalkulation!$A$44) | B36: =IF(Kalkulation!$B$44="","",Kalkulation!$C$44) | C36: =IF(Kalkulation!$B$44="","",Kalkulation!$E$44) | D36: =IF(Kalkulation!$B$44="","",Kalkulation!$D$44) | E36: =IF(Kalkulation!$B$44="","",Kalkulation!$L$44) | F36: =IF(Kalkulation!$B$44="","",Kalkulation!$M$44)
D38: Zwischensumme Positionen | F38: =Kalkulation!$M$46 -> 3212.34
D39: An- und Abfahrt | F39: =Kalkulation!$M$47 -> 28.56
D40: Rabatt | F40: =Kalkulation!$M$49 -> 0
D41: Nettobetrag | F41: =Kalkulation!$M$50 -> 3240.9
D42: =" zzgl. "&TEXT(Stammdaten!$B$21,"0 %")&" Umsatzsteuer" -> zzgl. 19 % Umsatzsteuer | F42: =Kalkulation!$M$51 -> 615.77
D43: Gesamtbetrag (brutto) | F43: =Kalkulation!$M$52 -> 3856.67
A46: ="Zahlungsbedingungen: "&TEXT(Stammdaten!$B$22,"0")&" Tage netto, bei Zahlung innerhalb von 8 Tagen "&TEXT(Stammdaten!$B$19,"0 %")&" Skonto." -> Zahlungsbedingungen: 14 Tage netto, bei Zahlung innerhalb von 8 Tagen 2 % Skonto.
A47: ="Dieses Angebot ist "&TEXT(Stammdaten!$B$23,"0")&" Tage ab Angebotsdatum gültig." -> Dieses Angebot ist 30 Tage ab Angebotsdatum gültig.
A48: Ausführungstermin nach Absprache. Es gelten unsere allgemeinen Geschäftsbedingungen.
...
